2025-02-16 21:09:41,707 - core.bot - INFO - Bot initialized
2025-02-16 21:09:41,759 - __main__ - INFO - Starting bot...
2025-02-16 21:09:41,759 - __main__ - ERROR - Error in main function: name 'Update' is not defined
2025-02-16 21:09:41,761 - __main__ - ERROR - Critical error: name 'Update' is not defined
2025-02-16 21:11:03,850 - core.bot - INFO - Bot initialized
2025-02-16 21:11:03,852 - __main__ - INFO - Starting bot...
2025-02-16 21:11:03,852 - __main__ - ERROR - Error in main function: name 'Update' is not defined
2025-02-16 21:11:03,853 - __main__ - ERROR - Critical error: name 'Update' is not defined
2025-02-16 21:34:11,531 - core.bot - INFO - Bot initialized
2025-02-16 21:34:11,532 - core.handler_registry - ERROR - Error registering handlers: 'Bot' object has no attribute 'handle_message'
2025-02-16 21:34:11,582 - core.application - ERROR - Error during setup: 'Bot' object has no attribute 'handle_message'
2025-02-16 21:34:11,582 - __main__ - ERROR - Error in main function: 'Bot' object has no attribute 'handle_message'
2025-02-16 21:34:11,583 - __main__ - ERROR - Critical error: 'Bot' object has no attribute 'handle_message'
2025-02-16 21:36:03,264 - core.application - ERROR - Error during setup: ConversationHandler main_conversation can not be persistent if application has no persistence
2025-02-16 21:36:03,265 - __main__ - ERROR - Error in main function: ConversationHandler main_conversation can not be persistent if application has no persistence
2025-02-16 21:36:03,266 - __main__ - ERROR - Critical error: ConversationHandler main_conversation can not be persistent if application has no persistence
2025-02-16 21:54:37,652 - core.application - ERROR - Error during setup: ConversationHandler message_conversation can not be persistent if application has no persistence
2025-02-16 21:54:37,652 - __main__ - ERROR - Error in main function: ConversationHandler message_conversation can not be persistent if application has no persistence
2025-02-16 21:54:37,653 - __main__ - ERROR - Critical error: ConversationHandler message_conversation can not be persistent if application has no persistence
2025-02-16 21:59:01,013 - core.bot - INFO - Bot initialized with token
2025-02-16 21:59:02,066 - core.bot - INFO - Handlers registered successfully
2025-02-16 21:59:02,067 - core.bot - INFO - Starting bot polling...
2025-02-16 21:59:02,495 - httpx - INFO - HTTP Request: POST https://api.telegram.org/bot7712419053:AAGFL_W-sf3hxcg_TlYPgL28Qtks4XA3980/getMe "HTTP/1.1 200 OK"
2025-02-16 21:59:02,498 - telegram.ext.Application - INFO - Application started
2025-02-16 21:59:02,756 - core.bot - ERROR - Error starting bot: Cannot close a running event loop
2025-02-16 21:59:02,756 - __main__ - ERROR - Error in main function: Cannot close a running event loop
2025-02-16 21:59:02,760 - __main__ - ERROR - Critical error: Cannot close a running event loop
2025-02-16 22:03:04,940 - core.bot - INFO - Bot initialized with token
2025-02-16 22:03:06,217 - core.bot - INFO - Handlers registered successfully
2025-02-16 22:03:06,217 - core.bot - INFO - Starting bot polling...
2025-02-16 22:03:06,671 - httpx - INFO - HTTP Request: POST https://api.telegram.org/bot7712419053:AAGFL_W-sf3hxcg_TlYPgL28Qtks4XA3980/getMe "HTTP/1.1 200 OK"
2025-02-16 22:03:06,673 - telegram.ext.Application - INFO - Application started
2025-02-16 22:03:06,937 - core.bot - ERROR - Error starting bot: Cannot close a running event loop
2025-02-16 22:03:06,938 - __main__ - ERROR - Error in main function: Cannot close a running event loop
2025-02-16 22:03:06,942 - __main__ - ERROR - Critical error: Cannot close a running event loop
2025-02-16 22:06:16,596 - core.bot - INFO - Bot initialized with token
2025-02-16 22:06:16,598 - __main__ - ERROR - Critical error: 
2025-02-16 22:11:58,785 - __main__ - INFO - Starting bot with token: 77124...
2025-02-16 22:11:58,786 - core.bot - INFO - Bot initialized with token
2025-02-16 22:11:58,786 - __main__ - ERROR - Error in main function: 
2025-02-16 22:11:58,883 - __main__ - ERROR - Traceback: Traceback (most recent call last):
  File "C:\ZOZ\main.py", line 46, in main
    loop.add_signal_handler(
    ~~~~~~~~~~~~~~~~~~~~~~~^
        sig,
        ^^^^
        lambda s=sig: asyncio.create_task(shutdown(bot, sig))
        ^^^^^^^^^^^^^^^^^^^^^^^^^^^^^^^^^^^^^^^^^^^^^^^^^^^^^
    )
    ^
  File "C:\Program Files\Python313\Lib\asyncio\events.py", line 596, in add_signal_handler
    raise NotImplementedError
NotImplementedError

2025-02-16 22:11:58,886 - __main__ - ERROR - Critical error: 
2025-02-16 22:11:58,894 - __main__ - ERROR - Full traceback: Traceback (most recent call last):
  File "C:\ZOZ\main.py", line 46, in main
    loop.add_signal_handler(
    ~~~~~~~~~~~~~~~~~~~~~~~^
        sig,
        ^^^^
        lambda s=sig: asyncio.create_task(shutdown(bot, sig))
        ^^^^^^^^^^^^^^^^^^^^^^^^^^^^^^^^^^^^^^^^^^^^^^^^^^^^^
    )
    ^
  File "C:\Program Files\Python313\Lib\asyncio\events.py", line 596, in add_signal_handler
    raise NotImplementedError
NotImplementedError

During handling of the above exception, another exception occurred:

Traceback (most recent call last):
  File "C:\ZOZ\main.py", line 69, in <module>
    asyncio.run(main())
    ~~~~~~~~~~~^^^^^^^^
  File "C:\Program Files\Python313\Lib\asyncio\runners.py", line 194, in run
    return runner.run(main)
           ~~~~~~~~~~^^^^^^
  File "C:\Program Files\Python313\Lib\asyncio\runners.py", line 118, in run
    return self._loop.run_until_complete(task)
           ~~~~~~~~~~~~~~~~~~~~~~~~~~~~~^^^^^^
  File "C:\Program Files\Python313\Lib\asyncio\base_events.py", line 721, in run_until_complete
    return future.result()
           ~~~~~~~~~~~~~^^
  File "C:\ZOZ\main.py", line 64, in main
    loop.remove_signal_handler(signal.SIGTERM)
    ~~~~~~~~~~~~~~~~~~~~~~~~~~^^^^^^^^^^^^^^^^
  File "C:\Program Files\Python313\Lib\asyncio\events.py", line 599, in remove_signal_handler
    raise NotImplementedError
NotImplementedError

2025-02-16 22:12:32,312 - __main__ - INFO - Starting bot with token: 77124...
2025-02-16 22:12:32,313 - core.bot - INFO - Bot initialized with token
2025-02-16 22:12:32,313 - __main__ - ERROR - Error in main function: 
2025-02-16 22:12:32,317 - __main__ - ERROR - Traceback: Traceback (most recent call last):
  File "C:\ZOZ\main.py", line 46, in main
    loop.add_signal_handler(
    ~~~~~~~~~~~~~~~~~~~~~~~^
        sig,
        ^^^^
        lambda s=sig: asyncio.create_task(shutdown(bot, sig))
        ^^^^^^^^^^^^^^^^^^^^^^^^^^^^^^^^^^^^^^^^^^^^^^^^^^^^^
    )
    ^
  File "C:\Program Files\Python313\Lib\asyncio\events.py", line 596, in add_signal_handler
    raise NotImplementedError
NotImplementedError

2025-02-16 22:12:32,319 - __main__ - ERROR - Critical error: 
2025-02-16 22:12:32,325 - __main__ - ERROR - Full traceback: Traceback (most recent call last):
  File "C:\ZOZ\main.py", line 46, in main
    loop.add_signal_handler(
    ~~~~~~~~~~~~~~~~~~~~~~~^
        sig,
        ^^^^
        lambda s=sig: asyncio.create_task(shutdown(bot, sig))
        ^^^^^^^^^^^^^^^^^^^^^^^^^^^^^^^^^^^^^^^^^^^^^^^^^^^^^
    )
    ^
  File "C:\Program Files\Python313\Lib\asyncio\events.py", line 596, in add_signal_handler
    raise NotImplementedError
NotImplementedError

During handling of the above exception, another exception occurred:

Traceback (most recent call last):
  File "C:\ZOZ\main.py", line 69, in <module>
    asyncio.run(main())
    ~~~~~~~~~~~^^^^^^^^
  File "C:\Program Files\Python313\Lib\asyncio\runners.py", line 194, in run
    return runner.run(main)
           ~~~~~~~~~~^^^^^^
  File "C:\Program Files\Python313\Lib\asyncio\runners.py", line 118, in run
    return self._loop.run_until_complete(task)
           ~~~~~~~~~~~~~~~~~~~~~~~~~~~~~^^^^^^
  File "C:\Program Files\Python313\Lib\asyncio\base_events.py", line 721, in run_until_complete
    return future.result()
           ~~~~~~~~~~~~~^^
  File "C:\ZOZ\main.py", line 64, in main
    loop.remove_signal_handler(signal.SIGTERM)
    ~~~~~~~~~~~~~~~~~~~~~~~~~~^^^^^^^^^^^^^^^^
  File "C:\Program Files\Python313\Lib\asyncio\events.py", line 599, in remove_signal_handler
    raise NotImplementedError
NotImplementedError

2025-02-16 22:17:13,458 - __main__ - INFO - Starting bot with token: 77124...
2025-02-16 22:17:13,459 - core.bot - INFO - Bot initialized with token
2025-02-16 22:17:13,460 - __main__ - ERROR - Error in main function: 
2025-02-16 22:17:13,464 - __main__ - ERROR - Traceback: Traceback (most recent call last):
  File "C:\ZOZ\main.py", line 46, in main
    loop.add_signal_handler(
    ~~~~~~~~~~~~~~~~~~~~~~~^
        sig,
        ^^^^
        lambda s=sig: asyncio.create_task(shutdown(bot, sig))
        ^^^^^^^^^^^^^^^^^^^^^^^^^^^^^^^^^^^^^^^^^^^^^^^^^^^^^
    )
    ^
  File "C:\Program Files\Python313\Lib\asyncio\events.py", line 596, in add_signal_handler
    raise NotImplementedError
NotImplementedError

2025-02-16 22:17:13,466 - __main__ - ERROR - Critical error: 
2025-02-16 22:17:13,472 - __main__ - ERROR - Full traceback: Traceback (most recent call last):
  File "C:\ZOZ\main.py", line 46, in main
    loop.add_signal_handler(
    ~~~~~~~~~~~~~~~~~~~~~~~^
        sig,
        ^^^^
        lambda s=sig: asyncio.create_task(shutdown(bot, sig))
        ^^^^^^^^^^^^^^^^^^^^^^^^^^^^^^^^^^^^^^^^^^^^^^^^^^^^^
    )
    ^
  File "C:\Program Files\Python313\Lib\asyncio\events.py", line 596, in add_signal_handler
    raise NotImplementedError
NotImplementedError

During handling of the above exception, another exception occurred:

Traceback (most recent call last):
  File "C:\ZOZ\main.py", line 69, in <module>
    asyncio.run(main())
    ~~~~~~~~~~~^^^^^^^^
  File "C:\Program Files\Python313\Lib\asyncio\runners.py", line 194, in run
    return runner.run(main)
           ~~~~~~~~~~^^^^^^
  File "C:\Program Files\Python313\Lib\asyncio\runners.py", line 118, in run
    return self._loop.run_until_complete(task)
           ~~~~~~~~~~~~~~~~~~~~~~~~~~~~~^^^^^^
  File "C:\Program Files\Python313\Lib\asyncio\base_events.py", line 721, in run_until_complete
    return future.result()
           ~~~~~~~~~~~~~^^
  File "C:\ZOZ\main.py", line 64, in main
    loop.remove_signal_handler(signal.SIGTERM)
    ~~~~~~~~~~~~~~~~~~~~~~~~~~^^^^^^^^^^^^^^^^
  File "C:\Program Files\Python313\Lib\asyncio\events.py", line 599, in remove_signal_handler
    raise NotImplementedError
NotImplementedError

2025-02-16 22:24:16,600 - __main__ - INFO - Starting bot with token: 77124...
2025-02-16 22:24:16,601 - core.bot - INFO - Bot initialized with token
2025-02-16 22:24:16,602 - __main__ - INFO - Starting bot...
2025-02-16 22:24:16,602 - core.bot - INFO - Creating application instance...
2025-02-16 22:24:17,754 - core.bot - INFO - Handlers registered successfully
2025-02-16 22:24:17,755 - core.bot - INFO - Starting bot polling...
2025-02-16 22:24:18,065 - core.bot - ERROR - Error starting bot: Cannot close a running event loop
Traceback (most recent call last):
  File "C:\ZOZ\venv\Lib\site-packages\telegram\ext\_application.py", line 1069, in __run
    loop.run_until_complete(self.initialize())
    ~~~~~~~~~~~~~~~~~~~~~~~^^^^^^^^^^^^^^^^^^^
  File "C:\Program Files\Python313\Lib\asyncio\base_events.py", line 697, in run_until_complete
    self._check_running()
    ~~~~~~~~~~~~~~~~~~~^^
  File "C:\Program Files\Python313\Lib\asyncio\base_events.py", line 633, in _check_running
    raise RuntimeError('This event loop is already running')
RuntimeError: This event loop is already running

During handling of the above exception, another exception occurred:

Traceback (most recent call last):
  File "C:\ZOZ\venv\Lib\site-packages\telegram\ext\_application.py", line 1094, in __run
    loop.run_until_complete(self.shutdown())
    ~~~~~~~~~~~~~~~~~~~~~~~^^^^^^^^^^^^^^^^^
  File "C:\Program Files\Python313\Lib\asyncio\base_events.py", line 697, in run_until_complete
    self._check_running()
    ~~~~~~~~~~~~~~~~~~~^^
  File "C:\Program Files\Python313\Lib\asyncio\base_events.py", line 633, in _check_running
    raise RuntimeError('This event loop is already running')
RuntimeError: This event loop is already running

During handling of the above exception, another exception occurred:

Traceback (most recent call last):
  File "C:\ZOZ\core\bot.py", line 45, in start
    await self.application.run_polling(allowed_updates=Update.ALL_TYPES)
          ~~~~~~~~~~~~~~~~~~~~~~~~~~~~^^^^^^^^^^^^^^^^^^^^^^^^^^^^^^^^^^
  File "C:\ZOZ\venv\Lib\site-packages\telegram\ext\_application.py", line 868, in run_polling
    return self.__run(
           ~~~~~~~~~~^
        updater_coroutine=self.updater.start_polling(
        ^^^^^^^^^^^^^^^^^^^^^^^^^^^^^^^^^^^^^^^^^^^^^
    ...<12 lines>...
        stop_signals=stop_signals,
        ^^^^^^^^^^^^^^^^^^^^^^^^^^
    )
    ^
  File "C:\ZOZ\venv\Lib\site-packages\telegram\ext\_application.py", line 1099, in __run
    loop.close()
    ~~~~~~~~~~^^
  File "C:\Program Files\Python313\Lib\asyncio\proactor_events.py", line 684, in close
    raise RuntimeError("Cannot close a running event loop")
RuntimeError: Cannot close a running event loop

2025-02-16 22:24:18,067 - __main__ - ERROR - Error in main function: Cannot close a running event loop
2025-02-16 22:24:18,074 - __main__ - ERROR - Traceback: Traceback (most recent call last):
  File "C:\ZOZ\venv\Lib\site-packages\telegram\ext\_application.py", line 1069, in __run
    loop.run_until_complete(self.initialize())
    ~~~~~~~~~~~~~~~~~~~~~~~^^^^^^^^^^^^^^^^^^^
  File "C:\Program Files\Python313\Lib\asyncio\base_events.py", line 697, in run_until_complete
    self._check_running()
    ~~~~~~~~~~~~~~~~~~~^^
  File "C:\Program Files\Python313\Lib\asyncio\base_events.py", line 633, in _check_running
    raise RuntimeError('This event loop is already running')
RuntimeError: This event loop is already running

During handling of the above exception, another exception occurred:

Traceback (most recent call last):
  File "C:\ZOZ\venv\Lib\site-packages\telegram\ext\_application.py", line 1094, in __run
    loop.run_until_complete(self.shutdown())
    ~~~~~~~~~~~~~~~~~~~~~~~^^^^^^^^^^^^^^^^^
  File "C:\Program Files\Python313\Lib\asyncio\base_events.py", line 697, in run_until_complete
    self._check_running()
    ~~~~~~~~~~~~~~~~~~~^^
  File "C:\Program Files\Python313\Lib\asyncio\base_events.py", line 633, in _check_running
    raise RuntimeError('This event loop is already running')
RuntimeError: This event loop is already running

During handling of the above exception, another exception occurred:

Traceback (most recent call last):
  File "C:\ZOZ\main.py", line 62, in main
    await bot.start()
  File "C:\ZOZ\core\bot.py", line 45, in start
    await self.application.run_polling(allowed_updates=Update.ALL_TYPES)
          ~~~~~~~~~~~~~~~~~~~~~~~~~~~~^^^^^^^^^^^^^^^^^^^^^^^^^^^^^^^^^^
  File "C:\ZOZ\venv\Lib\site-packages\telegram\ext\_application.py", line 868, in run_polling
    return self.__run(
           ~~~~~~~~~~^
        updater_coroutine=self.updater.start_polling(
        ^^^^^^^^^^^^^^^^^^^^^^^^^^^^^^^^^^^^^^^^^^^^^
    ...<12 lines>...
        stop_signals=stop_signals,
        ^^^^^^^^^^^^^^^^^^^^^^^^^^
    )
    ^
  File "C:\ZOZ\venv\Lib\site-packages\telegram\ext\_application.py", line 1099, in __run
    loop.close()
    ~~~~~~~~~~^^
  File "C:\Program Files\Python313\Lib\asyncio\proactor_events.py", line 684, in close
    raise RuntimeError("Cannot close a running event loop")
RuntimeError: Cannot close a running event loop

2025-02-16 22:24:18,076 - __main__ - INFO - Shutting down...
2025-02-16 22:24:18,077 - core.bot - INFO - Stopping bot...
2025-02-16 22:24:18,077 - core.bot - ERROR - Error stopping bot: 'Application' object has no attribute 'stop_polling'
2025-02-16 22:24:18,078 - __main__ - ERROR - Error during shutdown: 'Application' object has no attribute 'stop_polling'
2025-02-16 22:24:18,092 - __main__ - ERROR - Traceback (most recent call last):
  File "C:\ZOZ\venv\Lib\site-packages\telegram\ext\_application.py", line 1069, in __run
    loop.run_until_complete(self.initialize())
    ~~~~~~~~~~~~~~~~~~~~~~~^^^^^^^^^^^^^^^^^^^
  File "C:\Program Files\Python313\Lib\asyncio\base_events.py", line 697, in run_until_complete
    self._check_running()
    ~~~~~~~~~~~~~~~~~~~^^
  File "C:\Program Files\Python313\Lib\asyncio\base_events.py", line 633, in _check_running
    raise RuntimeError('This event loop is already running')
RuntimeError: This event loop is already running

During handling of the above exception, another exception occurred:

Traceback (most recent call last):
  File "C:\ZOZ\venv\Lib\site-packages\telegram\ext\_application.py", line 1094, in __run
    loop.run_until_complete(self.shutdown())
    ~~~~~~~~~~~~~~~~~~~~~~~^^^^^^^^^^^^^^^^^
  File "C:\Program Files\Python313\Lib\asyncio\base_events.py", line 697, in run_until_complete
    self._check_running()
    ~~~~~~~~~~~~~~~~~~~^^
  File "C:\Program Files\Python313\Lib\asyncio\base_events.py", line 633, in _check_running
    raise RuntimeError('This event loop is already running')
RuntimeError: This event loop is already running

During handling of the above exception, another exception occurred:

Traceback (most recent call last):
  File "C:\ZOZ\main.py", line 62, in main
    await bot.start()
  File "C:\ZOZ\core\bot.py", line 45, in start
    await self.application.run_polling(allowed_updates=Update.ALL_TYPES)
          ~~~~~~~~~~~~~~~~~~~~~~~~~~~~^^^^^^^^^^^^^^^^^^^^^^^^^^^^^^^^^^
  File "C:\ZOZ\venv\Lib\site-packages\telegram\ext\_application.py", line 868, in run_polling
    return self.__run(
           ~~~~~~~~~~^
        updater_coroutine=self.updater.start_polling(
        ^^^^^^^^^^^^^^^^^^^^^^^^^^^^^^^^^^^^^^^^^^^^^
    ...<12 lines>...
        stop_signals=stop_signals,
        ^^^^^^^^^^^^^^^^^^^^^^^^^^
    )
    ^
  File "C:\ZOZ\venv\Lib\site-packages\telegram\ext\_application.py", line 1099, in __run
    loop.close()
    ~~~~~~~~~~^^
  File "C:\Program Files\Python313\Lib\asyncio\proactor_events.py", line 684, in close
    raise RuntimeError("Cannot close a running event loop")
RuntimeError: Cannot close a running event loop

During handling of the above exception, another exception occurred:

Traceback (most recent call last):
  File "C:\ZOZ\main.py", line 27, in shutdown
    await bot.stop()
  File "C:\ZOZ\core\bot.py", line 59, in stop
    await self.application.stop_polling()
          ^^^^^^^^^^^^^^^^^^^^^^^^^^^^^
AttributeError: 'Application' object has no attribute 'stop_polling'. Did you mean: 'run_polling'?

2025-02-16 22:24:18,096 - __main__ - ERROR - Critical error: Cannot close a running event loop
2025-02-16 22:24:18,105 - __main__ - ERROR - Full traceback: Traceback (most recent call last):
  File "C:\ZOZ\venv\Lib\site-packages\telegram\ext\_application.py", line 1069, in __run
    loop.run_until_complete(self.initialize())
    ~~~~~~~~~~~~~~~~~~~~~~~^^^^^^^^^^^^^^^^^^^
  File "C:\Program Files\Python313\Lib\asyncio\base_events.py", line 697, in run_until_complete
    self._check_running()
    ~~~~~~~~~~~~~~~~~~~^^
  File "C:\Program Files\Python313\Lib\asyncio\base_events.py", line 633, in _check_running
    raise RuntimeError('This event loop is already running')
RuntimeError: This event loop is already running

During handling of the above exception, another exception occurred:

Traceback (most recent call last):
  File "C:\ZOZ\venv\Lib\site-packages\telegram\ext\_application.py", line 1094, in __run
    loop.run_until_complete(self.shutdown())
    ~~~~~~~~~~~~~~~~~~~~~~~^^^^^^^^^^^^^^^^^
  File "C:\Program Files\Python313\Lib\asyncio\base_events.py", line 697, in run_until_complete
    self._check_running()
    ~~~~~~~~~~~~~~~~~~~^^
  File "C:\Program Files\Python313\Lib\asyncio\base_events.py", line 633, in _check_running
    raise RuntimeError('This event loop is already running')
RuntimeError: This event loop is already running

During handling of the above exception, another exception occurred:

Traceback (most recent call last):
  File "C:\ZOZ\main.py", line 78, in <module>
    asyncio.run(main())
    ~~~~~~~~~~~^^^^^^^^
  File "C:\Program Files\Python313\Lib\asyncio\runners.py", line 194, in run
    return runner.run(main)
           ~~~~~~~~~~^^^^^^
  File "C:\Program Files\Python313\Lib\asyncio\runners.py", line 118, in run
    return self._loop.run_until_complete(task)
           ~~~~~~~~~~~~~~~~~~~~~~~~~~~~~^^^^^^
  File "C:\Program Files\Python313\Lib\asyncio\base_events.py", line 721, in run_until_complete
    return future.result()
           ~~~~~~~~~~~~~^^
  File "C:\ZOZ\main.py", line 62, in main
    await bot.start()
  File "C:\ZOZ\core\bot.py", line 45, in start
    await self.application.run_polling(allowed_updates=Update.ALL_TYPES)
          ~~~~~~~~~~~~~~~~~~~~~~~~~~~~^^^^^^^^^^^^^^^^^^^^^^^^^^^^^^^^^^
  File "C:\ZOZ\venv\Lib\site-packages\telegram\ext\_application.py", line 868, in run_polling
    return self.__run(
           ~~~~~~~~~~^
        updater_coroutine=self.updater.start_polling(
        ^^^^^^^^^^^^^^^^^^^^^^^^^^^^^^^^^^^^^^^^^^^^^
    ...<12 lines>...
        stop_signals=stop_signals,
        ^^^^^^^^^^^^^^^^^^^^^^^^^^
    )
    ^
  File "C:\ZOZ\venv\Lib\site-packages\telegram\ext\_application.py", line 1099, in __run
    loop.close()
    ~~~~~~~~~~^^
  File "C:\Program Files\Python313\Lib\asyncio\proactor_events.py", line 684, in close
    raise RuntimeError("Cannot close a running event loop")
RuntimeError: Cannot close a running event loop

